<?xml version="1.0"?>
<robot xmlns:xacro="http://www.ros.org/wiki/xacro" name="mon_robot">

  <!-- Base -->
  <link name="base_link">
    <inertial>
      <mass value="2.0"/>
      <inertia ixx="0.01" ixy="0" ixz="0" iyy="0.01" iyz="0" izz="0.01"/>
    </inertial>
    <visual>
      <geometry>
        <box size="0.3 0.3 0.2"/>
      </geometry>
      <material name="blue">
        <color rgba="0 0 1 1"/>
      </material>
    </visual>
    <collision>
      <geometry>
        <box size="0.3 0.3 0.2"/>
      </geometry>
    </collision>
  </link>

  <!-- Joint 1 (rotation base) -->
  <joint name="joint1" type="revolute">
    <parent link="base_link"/>
    <child link="link1"/>
    <origin xyz="0 0 0.1" rpy="0 0 0"/>
    <axis xyz="0 0 1"/>
    <limit lower="-1.57" upper="1.57" effort="10" velocity="1.0"/>
    <dynamics damping="0.1" friction="0.0"/>
  </joint>

  <link name="link1">
    <inertial>
      <mass value="1.0"/>
      <inertia ixx="0.005" ixy="0" ixz="0" iyy="0.005" iyz="0" izz="0.001"/>
    </inertial>
    <visual>
      <geometry>
        <box size="0.05 0.05 0.3"/>
      </geometry>
      <origin xyz="0 0 0.15"/>
      <material name="red">
        <color rgba="1 0 0 1"/>
      </material>
    </visual>
    <collision>
      <geometry>
        <box size="0.05 0.05 0.3"/>
      </geometry>
      <origin xyz="0 0 0.15"/>
    </collision>
  </link>

  <!-- Joint 2 (articulation bras) -->
  <joint name="joint2" type="revolute">
    <parent link="link1"/>
    <child link="link2"/>
    <origin xyz="0 0 0.3" rpy="0 0 0"/>
    <axis xyz="0 1 0"/>
    <limit lower="-1.57" upper="1.57" effort="10" velocity="1.0"/>
    <dynamics damping="0.1" friction="0.0"/>
  </joint>

  <link name="link2">
    <inertial>
      <mass value="0.5"/>
      <inertia ixx="0.002" ixy="0" ixz="0" iyy="0.002" iyz="0" izz="0.0005"/>
    </inertial>
    <visual>
      <geometry>
        <box size="0.04 0.04 0.25"/>
      </geometry>
      <origin xyz="0 0 0.125"/>
      <material name="green">
        <color rgba="0 1 0 1"/>
      </material>
    </visual>
    <collision>
      <geometry>
        <box size="0.04 0.04 0.25"/>
      </geometry>
      <origin xyz="0 0 0.125"/>
    </collision>
  </link>

  <!-- Gazebo plugin pour ros2_control -->
  <gazebo>
    <plugin filename="gz_ros2_control/GazeboSimSystem" name="gazebo_ros2_control">
      <parameters>$(find mon_robot_description)/config/controllers.yaml</parameters>
      <joint name="joint1">
        <command_interface name="effort"/>
        <state_interface name="position"/>
        <state_interface name="velocity"/>
      </joint>
      <joint name="joint2">
        <command_interface name="effort"/>
        <state_interface name="position"/>
        <state_interface name="velocity"/>
      </joint>
    </plugin>
  </gazebo>

</robot>
